<?xml version="1.0" encoding="utf-8"?>
<!-- This URDF was automatically created by SolidWorks to URDF Exporter! Originally created by Stephen Brawner (brawner@gmail.com) 
     Commit Version: 1.6.0-4-g7f85cfe  Build Version: 1.6.7995.38578
     For more information, please see http://wiki.ros.org/sw_urdf_exporter -->
<robot
  name="Assem6">
  <link
    name="base_link">
    <inertial>
      <origin
        xyz="0.0364762317678469 0.0405022880821174 -0.0701927583866328"
        rpy="0 0 0" />
      <mass
        value="52.0571714620044" />
      <inertia
        ixx="5.7499105501999"
        ixy="-1.45037852114768E-14"
        ixz="1.32797091627014E-18"
        iyy="6.76212527113026"
        iyz="0.00998612038496078"
        izz="12.4934134402393" />
    </inertial>
    <visual>
      <origin
        xyz="0 0 0"
        rpy="0 0 0" />
      <geometry>
        <mesh
          filename="package://Assem6/meshes/base_link.STL" />
      </geometry>
      <material
        name="">
        <color
          rgba="1 1 1 1" />
      </material>
    </visual>
    <collision>
      <origin
        xyz="0 0 0"
        rpy="0 0 0" />
      <geometry>
        <mesh
          filename="package://Assem6/meshes/base_link.STL" />
      </geometry>
    </collision>
  </link>
  <link
    name="link1">
    <inertial>
      <origin
        xyz="8.69317530254737E-06 -0.013117555669963 0.0968836990883351"
        rpy="0 0 0" />
      <mass
        value="0.55220141789339" />
      <inertia
        ixx="0.00254125787652368"
        ixy="2.27964754635378E-07"
        ixz="1.19504023573589E-07"
        iyy="0.00232524179834306"
        iyz="-2.9895991129839E-05"
        izz="0.00220431770359684" />
    </inertial>
    <visual>
      <origin
        xyz="0 0 0"
        rpy="0 0 0" />
      <geometry>
        <mesh
          filename="package://Assem6/meshes/link1.STL" />
      </geometry>
      <material
        name="">
        <color
          rgba="1 1 1 1" />
      </material>
    </visual>
    <collision>
      <origin
        xyz="0 0 0"
        rpy="0 0 0" />
      <geometry>
        <mesh
          filename="package://Assem6/meshes/link1.STL" />
      </geometry>
    </collision>
  </link>
  <joint
    name="joint1"
    type="continuous">
    <origin
      xyz="0.033986 -0.081844 0.011835"
      rpy="0 0 0" />
    <parent
      link="base_link" />
    <child
      link="link1" />
    <axis
      xyz="0 0 -1" />
    <limit
      lower="0"
      upper="6.28"
      effort="0"
      velocity="0" />
  </joint>
  <link
    name="link2">
    <inertial>
      <origin
        xyz="-5.05223423605261E-06 0.200565341638655 0.103941707991875"
        rpy="0 0 0" />
      <mass
        value="1.44588397633071" />
      <inertia
        ixx="0.0406605393459049"
        ixy="3.05406450114681E-07"
        ixz="4.4762049332157E-07"
        iyy="0.0055507603961306"
        iyz="0.00148559993678533"
        izz="0.0404243150281363" />
    </inertial>
    <visual>
      <origin
        xyz="0 0 0"
        rpy="0 0 0" />
      <geometry>
        <mesh
          filename="package://Assem6/meshes/link2.STL" />
      </geometry>
      <material
        name="">
        <color
          rgba="1 1 1 1" />
      </material>
    </visual>
    <collision>
      <origin
        xyz="0 0 0"
        rpy="0 0 0" />
      <geometry>
        <mesh
          filename="package://Assem6/meshes/link2.STL" />
      </geometry>
    </collision>
  </link>
  <joint
    name="joint2"
    type="revolute">
    <origin
      xyz="0 -0.0625 0.09129"
      rpy="1.5707963267949 0 0" />
    <parent
      link="link1" />
    <child
      link="link2" />
    <axis
      xyz="0 0 -1" />
    <limit
      lower="0"
      upper="1.57"
      effort="0"
      velocity="0" />
  </joint>
  <link
    name="link3">
    <inertial>
      <origin
        xyz="1.55829146690489E-07 0.191996125533032 0.0738008999598974"
        rpy="0 0 0" />
      <mass
        value="1.6414161965092" />
      <inertia
        ixx="0.0394815130415357"
        ixy="4.17420019419887E-09"
        ixz="-1.6167361324544E-08"
        iyy="0.00643251678314752"
        iyz="5.18708372989459E-18"
        izz="0.0382345589097705" />
    </inertial>
    <visual>
      <origin
        xyz="0 0 0"
        rpy="0 0 0" />
      <geometry>
        <mesh
          filename="package://Assem6/meshes/link3.STL" />
      </geometry>
      <material
        name="">
        <color
          rgba="1 1 1 1" />
      </material>
    </visual>
    <collision>
      <origin
        xyz="0 0 0"
        rpy="0 0 0" />
      <geometry>
        <mesh
          filename="package://Assem6/meshes/link3.STL" />
      </geometry>
    </collision>
  </link>
  <joint
    name="joint3"
    type="revolute">
    <origin
      xyz="0 0.378542203070813 0.0288"
      rpy="-3.14159265358979 0 3.14159265358979" />
    <parent
      link="link2" />
    <child
      link="link3" />
    <axis
      xyz="0 0 -1" />
    <limit
      lower="-1.57"
      upper="0"
      effort="0"
      velocity="0" />
  </joint>
  <link
    name="link4">
    <inertial>
      <origin
        xyz="-1.62231890976638E-08 0.0468478893722029 -0.0399806542724968"
        rpy="0 0 0" />
      <mass
        value="0.327437027139841" />
      <inertia
        ixx="0.000698216473077601"
        ixy="1.91298217640004E-11"
        ixz="1.58559506384301E-11"
        iyy="0.000366886774334359"
        iyz="-1.66508577977897E-07"
        izz="0.000445745149597185" />
    </inertial>
    <visual>
      <origin
        xyz="0 0 0"
        rpy="0 0 0" />
      <geometry>
        <mesh
          filename="package://Assem6/meshes/link4.STL" />
      </geometry>
      <material
        name="">
        <color
          rgba="1 1 1 1" />
      </material>
    </visual>
    <collision>
      <origin
        xyz="0 0 0"
        rpy="0 0 0" />
      <geometry>
        <mesh
          filename="package://Assem6/meshes/link4.STL" />
      </geometry>
    </collision>
  </link>
  <joint
    name="joint4"
    type="continuous">
    <origin
      xyz="0 0.39129 0.1158"
      rpy="0 0 0" />
    <parent
      link="link3" />
    <child
      link="link4" />
    <axis
      xyz="0 0 -1" />
    <limit
      lower="0"
      upper="3.14"
      effort="0"
      velocity="0" />
  </joint>
</robot>